Workbook

Sheet OverAll
C1: DateDiff | D1: Code | E1: CodeDiff | F1: Ratio(CodeDiff/Code)
B2: Average | C2: =AVERAGE(C6:C14) -> 132.5442 | D2: =AVERAGE(D6:D14) -> 126136.36 | E2: =AVERAGE(E6:E14) -> 2410.9728 | F2: =AVERAGE(F6:F14) -> 0.027332247
B3: Median | C3: =MEDIAN(C6:C14) -> 117 | D3: =MEDIAN(D6:D14) -> 90999.844 | E3: =MEDIAN(E6:E14) -> 602.33333 | F3: =MEDIAN(F6:F14) -> 0.022802567
B4: Stdev | C4: =STDEV(C6:C14) -> 106.56656 | D4: =STDEV(D6:D14) -> 178118.85 | E4: =STDEV(E6:E14) -> 4034.7922 | F4: =STDEV(F6:F14) -> 0.021533982
A5: Subject
A6: OpenChord | C6: =OpenChord!C2 -> 201.6 | D6: =OpenChord!D2 -> 8299.1667 | E6: =OpenChord!E2 -> 511 | F6: =OpenChord!F2 -> 0.061405751
A7: Thrift | C7: =Thrift!C2 -> 315.75 | D7: =Thrift!D2 -> 10583.846 | E7: =Thrift!E2 -> 602.33333 | F7: =Thrift!F2 -> 0.060905571
A8: xSocket | C8: =xSocket!C2 -> 28.482759 | D8: =xSocket!D2 -> 12796.633 | E8: =xSocket!E2 -> 316.27586 | F8: =xSocket!F2 -> 0.036270653
A9: Voldemort | C9: =Voldemort!C2 -> 19.1375 | D9: =Voldemort!D2 -> 103184.65 | E9: =Voldemort!E2 -> 229.725 | F9: =Voldemort!F2 -> 0.0024136836
A10: ZooKeeper | C10: =Zookeeper!C2 -> 177.03333 | D10: =Zookeeper!D2 -> 49683.382 | E10: =Zookeeper!E2 -> 521.33333 | F10: =Zookeeper!F2 -> 0.010083603
A11: Netty | C11: =Netty!C2 -> 41.092593 | D11: =Netty!D2 -> 92949.962 | E11: =Netty!E2 -> 746.84713 | F11: =Netty!F2 -> 0.0091914695
A12: Derby | C12: =Derby!C2 -> 240.9 | D12: =Derby!D2 -> 574003.22 | E12: =Derby!E2 -> 12573.091 | F12: =Derby!F2 -> 0.022802567
A13: Karaf | C13: =Karaf!C2 -> 117 | D13: =Karaf!D2 -> 90999.844 | E13: =Karaf!E2 -> 1747.4 | F13: =Karaf!F2 -> 0.01994631
A14: Cassandra | C14: =Cassandra!C2 -> 51.901578 | D14: =Cassandra!D2 -> 192726.5 | E14: =Cassandra!E2 -> 4450.75 | F14: =Cassandra!F2 -> 0.022970612
A15: XNIO | C15: =XNIO!C2 -> 161.8 | D15: =XNIO!D2 -> 8552.5714 | E15: =XNIO!E2 -> 357.4 | F15: =XNIO!F2 -> 0.069266324

Sheet OpenChord
C1: DateDiff | D1: Code | E1: CodeDiff | F1: Ratio(CodeDiff/Code)
B2: Average | C2: =AVERAGE(C6:C10) -> 201.6 | D2: =AVERAGE(D6:D11) -> 8299.1667 | E2: =AVERAGE(E7:E11) -> 511 | F2: =AVERAGE(F7:F11) -> 0.061405751
B3: Median | C3: =MEDIAN(C6:C10) -> 187 | D3: =MEDIAN(D6:D11) -> 8278 | E3: =MEDIAN(E7:E11) -> 607 | F3: =MEDIAN(F7:F11) -> 0.072572932
B4: Stdev | C4: =STDEV(C6:C10) -> 156.44744 | D4: =STDEV(D6:D11) -> 524.44844 | E4: =STDEV(E7:E11) -> 207.28362 | F4: =STDEV(F7:F11) -> 0.025536868
A5: Version | B5: Start_Date
A6: v1.0 | B6: 38748 | C6: =DATEDIF(B6,B7,"d") -> 339 | D6: 7792
A7: v1.0.1 | B7: 39087 | C7: =DATEDIF(B7,B8,"d") -> 7 | D7: 7839 | E7: 331 | F7: =E7/D7 -> 0.042224774
A8: v1.0.2 | B8: 39094 | C8: =DATEDIF(B8,B9,"d") -> 187 | D8: 8213 | E8: 686 | F8: =E8/D8 -> 0.083526117
A9: v1.0.3 | B9: 39281 | C9: =DATEDIF(B9,B10,"d") -> 99 | D9: 8343 | E9: 684 | F9: =E9/D9 -> 0.081984898
A10: v1.0.4 | B10: 39380 | C10: =DATEDIF(B10,B11,"d") -> 376 | D10: 8364 | E10: 607 | F10: =E10/D10 -> 0.072572932
A11: v1.0.5 | B11: 39756 | D11: 9244 | E11: 247 | F11: =E11/D11 -> 0.026720035

Sheet Thrift
C1: DateDiff | D1: Code | E1: CodeDiff | F1: Ratio(CodeDiff/Code)
B2: Average | C2: =AVERAGE(C15:C19) -> 315.75 | D2: =AVERAGE(D6:D19) -> 10583.846 | E2: =AVERAGE(E7:E19) -> 602.33333 | F2: =AVERAGE(F6:F19) -> 0.060905571
B3: Median | C3: =MEDIAN(C15:C19) -> 315 | D3: =MEDIAN(D6:D19) -> 10230 | E3: =MEDIAN(E7:E19) -> 569.5 | F3: =MEDIAN(F6:F19) -> 0.043825086
B4: Stdev | C4: =STDEV(C15:C19) -> 112.0398 | D4: =STDEV(D6:D19) -> 2595.9182 | E4: =STDEV(E7:E19) -> 487.9751 | F4: =STDEV(F6:F19) -> 0.055818243
A5: Version | B5: Start_Date
A6: V0.2.0 | B6: 41672 | C6: =DATEDIF(B6,B7,"d") -> 0 | D6: 6417
A7: V0.3.0 | B7: 41672 | C7: =DATEDIF(B7,B8,"d") -> 0 | D7: 6830 | E7: 984 | F7: =E7/D7 -> 0.14407028
A8: V0.4.0 | B8: 41672 | C8: =DATEDIF(B8,B9,"d") -> 0 | D8: 7903 | E8: 909 | F8: =E8/D8 -> 0.11501961
A9: V0.5.0 | B9: 41672 | C9: =DATEDIF(B9,B10,"d") -> 0 | D9: 8913 | E9: 296 | F9: =E9/D9 -> 0.033209918
A10: V0.6.0 | B10: 41672 | C10: =DATEDIF(B10,B11,"d") -> 0 | D10: 10093 | E10: 1828 | F10: =E10/D10 -> 0.18111562
A11: V0.6.1 | B11: 41672 | C11: =DATEDIF(B11,B12,"d") -> 0 | D11: 10093 | E11: 126 | F11: =E11/D11 -> 0.0124839
A12: V0.7.0 | B12: 41672 | C12: =DATEDIF(B12,B13,"d") -> 0 | D12: 10230 | E12: 179 | F12: =E12/D12 -> 0.017497556
A13: V0.8.0 | B13: 41672 | C13: =DATEDIF(B13,B14,"d") -> 0 | D13: 11163 | E13: 650 | F13: =E13/D13 -> 0.058228075
A14: V0.9.0 | B14: 41672 | C14: =DATEDIF(B14,B15,"d") -> 0 | D14: 11661 | E14: 189 | F14: =E14/D14 -> 0.016207872
A15: V0.9.1 | B15: 41672 | C15: =DATEDIF(B15,B25,"d") -> 180 | D15: 12635 | E15: 543 | F15: =E15/D15 -> 0.042975861
A17: V0.9.2 | B17: 41959 | C17: =DATEDIF(B17,B18,"d") -> 329 | D17: 13341 | E17: 596 | F17: =E17/D17 -> 0.044674312
A18: V0.9.3 | B18: 42288 | C18: =DATEDIF(B18,B19,"d") -> 453 | D18: 14094 | E18: 179 | F18: =E18/D18 -> 0.01270044
A19: V0.10.0 | B19: 42741 | C19: =DATEDIF(B19,B20,"d") -> 301 | D19: 14217 | E19: 749 | F19: =E19/D19 -> 0.052683407
A20: V0.11.0 | B20: 43042 | D20: 14510 | E20: 209 | F20: =E20/D20 -> 0.014403859
D21: =SUM(D6:D20) -> 152100
A25: hier | B25: 41852 | C25: =DATEDIF(B25,B17,"d") -> 107 | D25: 13238 | E25: 910 | F25: =E25/D25 -> 0.068741502

Sheet xSocket
C1: DateDiff | D1: Code | E1: CodeDiff | F1: Ratio(CodeDiff/Code)
B2: Average | C2: =AVERAGE(C6:C65) -> 28.482759 | D2: =AVERAGE(D6:D65) -> 12796.633 | E2: =AVERAGE(E7:E65) -> 316.27586 | F2: =AVERAGE(F7:F65) -> 0.036270653
B3: Median | C3: =MEDIAN(C6:C65) -> 15 | D3: =MEDIAN(D6:D65) -> 14096 | E3: =MEDIAN(E7:E65) -> 160 | F3: =MEDIAN(F7:F65) -> 0.010335594
B4: Stdev | C4: =STDEV(C6:C65) -> 34.507686 | D4: =STDEV(D6:D65) -> 3674.1422 | E4: =STDEV(E7:E65) -> 346.40909 | F4: =STDEV(F7:F65) -> 0.055654696
A5: Version | B5: Start_Date
A6: V0.9-beta-1 | B6: 38915 | C6: =DATEDIF(B6,B7,"d") -> 62 | D6: 2331
A7: V1.0-beta-1 | B7: 38977 | C7: =DATEDIF(B7,B8,"d") -> 87 | D7: 2399 | E7: 383 | F7: =E7/D7 -> 0.15964985
A8: V1.0-beta-2 | B8: 39064 | C8: =DATEDIF(B8,B9,"d") -> 35 | D8: 3252 | E8: 968 | F8: =E8/D8 -> 0.29766298
A9: V1.0-beta-3 | B9: 39099 | C9: =DATEDIF(B9,B10,"d") -> 35 | D9: 4237 | E9: 188 | F9: =E9/D9 -> 0.044371017
A10: V1.0-beta-4 | B10: 39134 | C10: =DATEDIF(B10,B11,"d") -> 29 | D10: 4522 | E10: 487 | F10: =E10/D10 -> 0.10769571
A11: V1.0 | B11: 39163 | C11: =DATEDIF(B11,B12,"d") -> 8 | D11: 5446 | E11: 991 | F11: =E11/D11 -> 0.18196842
A12: V1.1 | B12: 39171 | C12: =DATEDIF(B12,B13,"d") -> 134 | D12: 7281 | E12: 999 | F12: =E12/D12 -> 0.13720643
A13: V1.2 | B13: 39305 | C13: =DATEDIF(B13,B14,"d") -> 66 | D13: 8717 | E13: 1342 | F13: =E13/D13 -> 0.15395205
A14: V1.2.1 | B14: 39371 | D14: 9001 | E14: 641 | F14: =E14/D14 -> 0.07121431
A15: V2.0-alpha-1 | B15: 39356 | C15: =DATEDIF(B15,B16,"d") -> 142 | D15: 8657
A16: V2.0-alpha-2 | B16: 39498 | C16: =DATEDIF(B16,B17,"d") -> 16 | D16: 10337 | E16: 678 | F16: =E16/D16 -> 0.065589629
A17: V2.0-beta-1 | B17: 39514 | C17: =DATEDIF(B17,B18,"d") -> 11 | D17: 10366 | E17: 435 | F17: =E17/D17 -> 0.041964113
A18: V2.0-beta-2 | B18: 39525 | C18: =DATEDIF(B18,B19,"d") -> 38 | D18: 10857 | E18: 651 | F18: =E18/D18 -> 0.059961315
A19: V2.0 | B19: 39563 | C19: =DATEDIF(B19,B20,"d") -> 55 | D19: 11657 | E19: 674 | F19: =E19/D19 -> 0.057819336
A20: V2.1 | B20: 39618 | C20: =DATEDIF(B20,B21,"d") -> 49 | D20: 12041 | E20: 765 | F20: =E20/D20 -> 0.063532929
A21: V2.1.1 | B21: 39667 | C21: =DATEDIF(B21,B22,"d") -> 34 | D21: 12213 | E21: 806 | F21: =E21/D21 -> 0.065995251
A22: V2.1.2 | B22: 39701 | C22: =DATEDIF(B22,B23,"d") -> 40 | D22: 12237 | E22: 19 | F22: =E22/D22 -> 0.0015526681
A23: V2.2 | B23: 39741 | C23: =DATEDIF(B23,B24,"d") -> 15 | D23: 12283 | E23: 668 | F23: =E23/D23 -> 0.054384108
A24: V2.3 | B24: 39756 | C24: =DATEDIF(B24,B25,"d") -> 25 | D24: 13340 | E24: 787 | F24: =E24/D24 -> 0.058995502
A25: V2.3.1 | B25: 39781 | C25: =DATEDIF(B25,B26,"d") -> 43 | D25: 13155 | E25: 745 | F25: =E25/D25 -> 0.056632459
A26: V2.3.2 | B26: 39824 | C26: =DATEDIF(B26,B27,"d") -> 15 | D26: 13160 | E26: 262 | F26: =E26/D26 -> 0.019908815
A27: V2.4 | B27: 39839 | C27: =DATEDIF(B27,B28,"d") -> 2 | D27: 13272 | E27: 267 | F27: =E27/D27 -> 0.020117541
... A64: V2.8.14 | B64: 40442 | C64: =DATEDIF(B64,B65,"d") -> 110 | D64: 15760 | E64: 13 | F64: =E64/D64 -> 0.0008248731
A65: V2.8.15 | B65: 40552 | D65: 15760 | E65: 10 | F65: =E65/D65 -> 0.00063451777
D66: =SUM(D6:D65) -> 767798

Sheet Voldemort
C1: DateDiff | D1: Code | E1: CodeDiff | F1: Ratio(CodeDiff/Code)
B2: Average | C2: =AVERAGE(C6:C86) -> 19.1375 | D2: =AVERAGE(D6:D86) -> 103184.65 | E2: =AVERAGE(E7:E86) -> 229.725 | F2: =AVERAGE(F6:F86) -> 0.0024136836
B3: Median | C3: =MEDIAN(C6:C86) -> 11 | D3: =MEDIAN(D6:D86) -> 103115 | E3: =MEDIAN(E7:E86) -> 75.5 | F3: =MEDIAN(F6:F86) -> 0.00077130737
B4: Stdev | C4: =STDEV(C6:C86) -> 31.249403 | D4: =STDEV(D6:D86) -> 9439.1845 | E4: =STDEV(E7:E86) -> 664.15585 | F4: =STDEV(F6:F86) -> 0.0074325217
A5: Version | B5: Start_Date
A6: V1.4.0 | B6: 41446 | C6: =DATEDIF(B6,B7,"d") -> 76 | D6: 84400
A7: V1.5.1 | B7: 41522 | C7: =DATEDIF(B7,B8,"d") -> 7 | D7: 87148 | E7: 3918 | F7: =E7/D7 -> 0.044958002
A8: V1.5.2 | B8: 41529 | C8: =DATEDIF(B8,B9,"d") -> 19 | D8: 87248 | E8: 75 | F8: =E8/D8 -> 0.00085961856
A9: V1.5.4 | B9: 41548 | C9: =DATEDIF(B9,B10,"d") -> 27 | D9: 87392 | E9: 187 | F9: =E9/D9 -> 0.002139784
A10: V1.5.7 | B10: 41575 | C10: =DATEDIF(B10,B11,"d") -> 1 | D10: 88250 | E10: 257 | F10: =E10/D10 -> 0.0029121813
A11: V1.5.8 | B11: 41576 | C11: =DATEDIF(B11,B12,"d") -> 27 | D11: 88295 | E11: 36 | F11: =E11/D11 -> 0.00040772411
A12: V1.5.9 | B12: 41603 | C12: =DATEDIF(B12,B13,"d") -> 1 | D12: 88295 | E12: 16 | F12: =E12/D12 -> 0.00018121071
A13: V1.6.0 | B13: 41604 | C13: =DATEDIF(B13,B14,"d") -> 17 | D13: 88336 | E13: 72 | F13: =E13/D13 -> 0.00081506973
A14: V1.6.1 | B14: 41621 | C14: =DATEDIF(B14,B15,"d") -> 28 | D14: 88680 | E14: 216 | F14: =E14/D14 -> 0.002435724
A15: V1.6.2 | B15: 41649 | C15: =DATEDIF(B15,B16,"d") -> 21 | D15: 90831 | E15: 4418 | F15: =E15/D15 -> 0.048639782
A16: V1.6.3 | B16: 41670 | C16: =DATEDIF(B16,B17,"d") -> 3 | D16: 90834 | E16: 3 | F16: =E16/D16 -> 3.3027281e-05
A17: V1.6.4 | B17: 41673 | C17: =DATEDIF(B17,B18,"d") -> 4 | D17: 91070 | E17: 15 | F17: =E17/D17 -> 0.00016470847
A18: V1.6.6 | B18: 41677 | C18: =DATEDIF(B18,B19,"d") -> 14 | D18: 91617 | E18: 238 | F18: =E18/D18 -> 0.0025977712
... A85: V1.10.25 | B85: 42943 | C85: =DATEDIF(B85,B86,"d") -> 34 | D85: 115279 | E85: 0 | F85: =E85/D85 -> 0
A86: V1.10.26 | B86: 42977 | D86: 115310 | E86: 28
D87: =SUM(D7:D86) -> 8273557

Sheet Zookeeper
C1: DateDiff | D1: Code | E1: CodeDiff | F1: Ratio(CodeDiff/Code)
B2: Average | C2: =AVERAGE(C6:C38) -> 177.03333 | D2: =AVERAGE(D6:D39) -> 49683.382 | E2: =AVERAGE(E7:E39) -> 521.33333 | F2: =AVERAGE(F6:F39) -> 0.010083603
B3: Median | C3: =MEDIAN(C6:C38) -> 154 | D3: =MEDIAN(D6:D39) -> 49775 | E3: =MEDIAN(E7:E39) -> 254 | F3: =MEDIAN(F6:F39) -> 0.0053238343
B4: Stdev | C4: =STDEV(C6:C38) -> 150.00195 | D4: =STDEV(D6:D39) -> 14771.476 | E4: =STDEV(E7:E39) -> 627.20542 | F4: =STDEV(F6:F39) -> 0.013277267
A5: Version | B5: Start_Date
A6: V3.0.0 | B6: 39748 | C6: =DATEDIF(B6,B7,"d") -> 8 | D6: 21566
A7: V3.0.1 | B7: 39756 | C7: =DATEDIF(B7,B8,"d") -> 101 | D7: 21796 | E7: 120 | F7: =E7/D7 -> 0.0055055974
A8: V3.1.0 | B8: 39857 | C8: =DATEDIF(B8,B9,"d") -> 42 | D8: 28419 | E8: 1331 | F8: =E8/D8 -> 0.046834864
A9: V3.1.1 | B9: 39899 | C9: =DATEDIF(B9,B10,"d") -> 232 | D9: 28435 | E9: 34 | F9: =E9/D9 -> 0.0011957095
A10: V3.1.2 | B10: 40131 | D10: 28644 | E10: 23 | F10: =E10/D10 -> 0.00080296048
A11: V3.2.0 | B11: 40002 | C11: =DATEDIF(B11,B12,"d") -> 58 | D11: 35044
A12: V3.2.1 | B12: 40060 | C12: =DATEDIF(B12,B13,"d") -> 0 | D12: 35740 | E12: 328 | F12: =E12/D12 -> 0.0091773923
A13: V3.2.2 | B13: 40060 | C13: =DATEDIF(B13,B14,"d") -> 202 | D13: 36016 | E13: 44 | F13: =E13/D13 -> 0.0012216793
A14: V3.3.0 | B14: 40262 | C14: =DATEDIF(B14,B15,"d") -> 53 | D14: 42747 | E14: 2445 | F14: =E14/D14 -> 0.057196996
A15: V3.3.1 | B15: 40315 | C15: =DATEDIF(B15,B16,"d") -> 178 | D15: 42940 | E15: 166 | F15: =E15/D15 -> 0.0038658593
A16: V3.3.2 | B16: 40493 | C16: =DATEDIF(B16,B17,"d") -> 108 | D16: 43542 | E16: 170 | F16: =E16/D16 -> 0.0039042763
A17: V3.3.3 | B17: 40601 | C17: =DATEDIF(B17,B18,"d") -> 272 | D17: 44736 | E17: 135 | F17: =E17/D17 -> 0.0030177039
A18: V3.3.4 | B18: 40873 | C18: =DATEDIF(B18,B19,"d") -> 115 | D18: 45416 | E18: 282 | F18: =E18/D18 -> 0.0062092655
A19: V3.3.5 | B19: 40988 | C19: =DATEDIF(B19,B20,"d") -> 135 | D19: 45834 | E19: 126 | F19: =E19/D19 -> 0.0027490509
A20: V3.3.6 | B20: 41123 | D20: 46402 | E20: 85 | F20: =E20/D20 -> 0.0018318176
A21: V3.4.0 | B21: 40869 | C21: =DATEDIF(B21,B22,"d") -> 24 | D21: 49635
A22: V3.4.1 | B22: 40893 | C22: =DATEDIF(B22,B23,"d") -> 13 | D22: 49752 | E22: 35 | F22: =E22/D22 -> 0.00070348931
A23: V3.4.2 | B23: 40906 | C23: =DATEDIF(B23,B24,"d") -> 46 | D23: 49798 | E23: 41 | F23: =E23/D23 -> 0.00082332624
A24: V3.4.3 | B24: 40952 | C24: =DATEDIF(B24,B25,"d") -> 223 | D24: 50355 | E24: 293 | F24: =E24/D24 -> 0.0058186873
A25: V3.4.4 | B25: 41175 | C25: =DATEDIF(B25,B26,"d") -> 56 | D25: 52447 | E25: 571 | F25: =E25/D25 -> 0.010887181
A26: V3.4.5 | B26: 41231 | C26: =DATEDIF(B26,B27,"d") -> 477 | D26: 52479 | E26: 47 | F26: =E26/D26 -> 0.00089559633
A27: V3.4.6 | B27: 41708 | C27: =DATEDIF(B27,B28,"d") -> 621 | D27: 55270 | E27: 843 | F27: =E27/D27 -> 0.015252397
A28: V3.4.7 | B28: 42329 | C28: =DATEDIF(B28,B29,"d") -> 91 | D28: 56649 | E28: 718 | F28: =E28/D28 -> 0.01267454
A29: V3.4.8 | B29: 42420 | C29: =DATEDIF(B29,B30,"d") -> 196 | D29: 56888 | E29: 50 | F29: =E29/D29 -> 0.00087891998
A30: V3.4.9 | B30: 42616 | C30: =DATEDIF(B30,B31,"d") -> 208 | D30: 57542 | E30: 156 | F30: =E30/D30 -> 0.0027110632
A31: V3.4.10 | B31: 42824 | C31: =DATEDIF(B31,B32,"d") -> 224 | D31: 61612 | E31: 677 | F31: =E31/D31 -> 0.010988119
A32: V3.4.11 | B32: 43048 | C32: =DATEDIF(B32,B33,"d") -> 173 | D32: 62194 | E32: 677 | F32: =E32/D32 -> 0.010885294
A33: V3.4.12 | B33: 43221 | C33: =DATEDIF(B33,B34,"d") -> 75 | D33: 62538 | E33: 226 | F33: =E33/D33 -> 0.0036138028
A34: V3.4.13 | B34: 43296 | D34: 63982 | E34: 329 | F34: =E34/D34 -> 0.0051420712
A35: V3.5.0 | B35: 41857 | C35: =DATEDIF(B35,B36,"d") -> 390 | D35: 66464
A36: V3.5.1 | B36: 42247 | C36: =DATEDIF(B36,B37,"d") -> 324 | D36: 69906 | E36: 1933 | F36: =E36/D36 -> 0.027651418
A37: V3.5.2 | B37: 42571 | C37: =DATEDIF(B37,B38,"d") -> 271 | D37: 71586 | E37: 839 | F37: =E37/D37 -> 0.011720169
A38: V3.5.3 | B38: 42842 | C38: =DATEDIF(B38,B39,"d") -> 395 | D38: 73995 | E38: 1647 | F38: =E38/D38 -> 0.022258261
A39: V3.5.4 | B39: 43237 | D39: 78866 | E39: 1269 | F39: =E39/D39 -> 0.016090584
D40: =SUM(D6:D39) -> 1689235

Sheet Netty
C1: DateDiff | D1: Code | E1: CodeDiff | F1: Ratio(CodeDiff/Code)
B2: Average | C2: =AVERAGE(C49:C162) -> 41.092593 | D2: =AVERAGE(D6:D163) -> 92949.962 | E2: =AVERAGE(E7:E163) -> 746.84713 | F2: =AVERAGE(F7:F163) -> 0.0091914695
B3: Median | C3: =MEDIAN(C49:C162) -> 31 | D3: =MEDIAN(D6:D163) -> 78187 | E3: =MEDIAN(E7:E163) -> 316 | F3: =MEDIAN(F7:F163) -> 0.0035948431
B4: Stdev | C4: =STDEV(C49:C162) -> 42.4853 | D4: =STDEV(D6:D163) -> 38276.547 | E4: =STDEV(E7:E163) -> 1298.4431 | F4: =STDEV(F7:F163) -> 0.017757329
A5: Version | B5: Start_Date
A6: 3.1.0 | B6: 41448 | C6: =DATEDIF(B6,B7,"d") -> 4 | D6: 38073
A7: 3.1.1 | B7: 41452 | C7: =DATEDIF(B7,B8,"d") -> 0 | D7: 38076 | E7: 55 | F7: =E7/D7 -> 0.0014444795
A8: 3.1.2 | B8: 41452 | C8: =DATEDIF(B8,B9,"d") -> 0 | D8: 38078 | E8: 11 | F8: =E8/D8 -> 0.00028888072
A9: 3.1.3 | B9: 41452 | C9: =DATEDIF(B9,B10,"d") -> 0 | D9: 38325 | E9: 4745 | F9: =E9/D9 -> 0.12380952
A10: 3.1.4 | B10: 41452 | C10: =DATEDIF(B10,B11,"d") -> 0 | D10: 38425 | E10: 99 | F10: =E10/D10 -> 0.0025764476
A11: 3.1.5 | B11: 41452 | D11: 38547 | E11: 1525 | F11: =E11/D11 -> 0.039562093
A12: 3.2.0 | B12: 41448 | C12: =DATEDIF(B12,B13,"d") -> 4 | D12: 45629 | E12: 4994 | F12: =E12/D12 -> 0.10944794
A13: 3.2.1 | B13: 41452 | C13: =DATEDIF(B13,B14,"d") -> 0 | D13: 45837 | E13: 1539 | F13: =E13/D13 -> 0.033575496
A14: 3.2.2 | B14: 41452 | C14: =DATEDIF(B14,B15,"d") -> 0 | D14: 45920 | E14: 197 | F14: =E14/D14 -> 0.0042900697
A15: 3.2.3 | B15: 41452 | C15: =DATEDIF(B15,B16,"d") -> 0 | D15: 45985 | E15: 219 | F15: =E15/D15 -> 0.0047624225
A16: 3.2.4 | B16: 41452 | C16: =DATEDIF(B16,B17,"d") -> 0 | D16: 46080 | E16: 275 | F16: =E16/D16 -> 0.0059678819
A17: 3.2.5 | B17: 41452 | C17: =DATEDIF(B17,B18,"d") -> 0 | D17: 46262 | E17: 287 | F17: =E17/D17 -> 0.0062037958
A18: 3.2.6 | B18: 41452 | C18: =DATEDIF(B18,B19,"d") -> 0 | D18: 46395 | E18: 194 | F18: =E18/D18 -> 0.0041814851
A19: 3.2.7 | B19: 41452 | C19: =DATEDIF(B19,B20,"d") -> 0 | D19: 47375 | E19: 673 | F19: =E19/D19 -> 0.014205805
A20: 3.3.0 | B20: 41452 | C20: =DATEDIF(B20,B21,"d") -> 0 | D20: 50719 | E20: 4477 | F20: =E20/D20 -> 0.088270668
A21: 3.3.1 | B21: 41452 | C21: =DATEDIF(B21,B22,"d") -> 0 | D21: 53382 | E21: 185 | F21: =E21/D21 -> 0.0034655877
A22: 3.4.0 | B22: 41452 | C22: =DATEDIF(B22,B23,"d") -> 0 | D22: 54836 | E22: 1472 | F22: =E22/D22 -> 0.026843679
A23: 3.4.1 | B23: 41452 | C23: =DATEDIF(B23,B24,"d") -> 0 | D23: 54997 | E23: 67 | F23: =E23/D23 -> 0.0012182483
... A51: 3.6.8 | B51: 41710 | C51: =DATEDIF(B51,B52,"d") -> 49 | D51: 69473 | E51: 9 | F51: =E51/D51 -> 0.00012954673
A52: 3.6.9 | B52: 41759 | D52: 69624 | E52: 44 | F52: =E52/D52 -> 0.00063196599
A53: 3.7.0 | B53: 41522 | C53: =DATEDIF(B53,B54,"d") -> 237 | D53: 69276 | E53: 945 | F53: =E53/D53 -> 0.013641088
A54: 3.7.1 | B54: 41759 | D54: 69471 | E54: 64 | F54: =E54/D54 -> 0.00092124771
A55: 3.8.0 | B55: 41585 | C55: =DATEDIF(B55,B56,"d") -> 174 | D55: 70378 | E55: 1665 | F55: =E55/D55 -> 0.023657961
A56: 3.8.2 | B56: 41759 | D56: 70626 | E56: 74 | F56: =E56/D56 -> 0.0010477728
A57: 3.9.0 | B57: 41630 | C57: =DATEDIF(B57,B58,"d") -> 129 | D57: 71350 | E57: 213 | F57: =E57/D57 -> 0.0029852838
A58: 3.9.1 | B58: 41759 | C58: =DATEDIF(B58,B59,"d") -> 42 | D58: 73728 | E58: 752 | F58: =E58/D58 -> 0.010199653
A59: 3.9.2 | B59: 41801 | C59: =DATEDIF(B59,B60,"d") -> 56 | D59: 75259 | E59: 2137 | F59: =E59/D59 -> 0.028395275
A60: 3.9.3 | B60: 41857 | C60: =DATEDIF(B60,B61,"d") -> 20 | D60: 75633 | E60: 159 | F60: =E60/D60 -> 0.002102257
A61: 3.9.4 | B61: 41877 | C61: =DATEDIF(B61,B62,"d") -> 65 | D61: 76483 | E61: 125 | F61: =E61/D61 -> 0.0016343501
A62: 3.9.5 | B62: 41942 | C62: =DATEDIF(B62,B63,"d") -> 48 | D62: 76575 | E62: 51 | F62: =E62/D62 -> 0.00066601371
A63: 3.9.6 | B63: 41990 | C63: =DATEDIF(B63,B64,"d") -> 81 | D63: 77333 | E63: 278 | F63: =E63/D63 -> 0.0035948431
A64: 3.9.7 | B64: 42071 | C64: =DATEDIF(B64,B65,"d") -> 61 | D64: 78459 | E64: 260 | F64: =E64/D64 -> 0.0033138327
A65: 3.9.8 | B65: 42132 | C65: =DATEDIF(B65,B66,"d") -> 74 | D65: 78459 | E65: 70 | F65: =E65/D65 -> 0.00089218573
A66: 3.9.9 | B66: 42206 | D66: 78474 | E66: 22 | F66: =E66/D66 -> 0.00028034763
A67: 3.10.0 | B67: 41990 | C67: =DATEDIF(B67,B68,"d") -> 96 | D67: 76987 | E67: 998 | F67: =E67/D67 -> 0.012963228
...

Sheet Derby
C1: DateDiff | D1: Code | E1: CodeDiff | F1: Ratio(CodeDiff/Code)
B2: Average | C2: =AVERAGE(C6:C27) -> 240.9 | D2: =AVERAGE(D6:D28) -> 574003.22 | E2: =AVERAGE(E7:E28) -> 12573.091 | F2: =AVERAGE(F7:F28) -> 0.022802567
B3: Median | C3: =MEDIAN(C6:C27) -> 206 | D3: =MEDIAN(D6:D28) -> 613782 | E3: =MEDIAN(E7:E28) -> 5118.5 | F3: =MEDIAN(F7:F28) -> 0.0085466821
B4: Stdev | C4: =STDEV(C6:C27) -> 151.25785 | D4: =STDEV(D6:D28) -> 97925.585 | E4: =STDEV(E7:E28) -> 14454.103 | F4: =STDEV(F7:F28) -> 0.028725433
A5: Version | B5: Start_Date
A6: 10.1.1.0 | B6: 38567 | C6: =DATEDIF(B6,B7,"d") -> 97 | D6: 391810
A7: 10.1.2.1 | B7: 38664 | C7: =DATEDIF(B7,B8,"d") -> 234 | D7: 393664 | E7: 7573 | F7: =E7/D7 -> 0.019237218
A8: 10.1.3.1 | B8: 38898 | C8: =DATEDIF(B8,B9,"d") -> 94 | D8: 398353 | E8: 3317 | F8: =E8/D8 -> 0.0083267855
A9: 10.2.1.6 | B9: 38992 | C9: =DATEDIF(B9,B10,"d") -> 71 | D9: 451483 | E9: 54907 | F9: =E9/D9 -> 0.12161477
A10: 10.2.2.0 | B10: 39063 | C10: =DATEDIF(B10,B11,"d") -> 517 | D10: 451591 | E10: 3839 | F10: =E10/D10 -> 0.0085010552
A11: 10.3.3.0 | B11: 39580 | D11: 505093 | E11: 32772 | F11: =E11/D11 -> 0.064883101
A12: 10.4.1.3 | B12: 39562 | C12: =DATEDIF(B12,B13,"d") -> 134 | D12: 535262 | E12: 19825 | F12: =E12/D12 -> 0.037037937
A13: 10.4.2.0 | B13: 39696 | C13: =DATEDIF(B13,B14,"d") -> 235 | D13: 537769 | E13: 2513 | F13: =E13/D13 -> 0.0046730102
A14: 10.5.1.1 | B14: 39931 | C14: =DATEDIF(B14,B15,"d") -> 115 | D14: 570702 | E14: 15281 | F14: =E14/D14 -> 0.026775795
A15: 10.5.3.0 | B15: 40046 | C15: =DATEDIF(B15,B16,"d") -> 271 | D15: 579725 | E15: 2136 | F15: =E15/D15 -> 0.0036845056
A16: 10.6.1.0 | B16: 40317 | C16: =DATEDIF(B16,B17,"d") -> 139 | D16: 617986 | E16: 19602 | F16: =E16/D16 -> 0.031719165
A17: 10.6.2.1 | B17: 40456 | C17: =DATEDIF(B17,B18,"d") -> 40 | D17: 637669 | E17: 1628 | F17: =E17/D17 -> 0.0025530487
A18: 10.7.1.1 | B18: 40496 | C18: =DATEDIF(B18,B19,"d") -> 166 | D18: 605076 | E18: 5199 | F18: =E18/D18 -> 0.0085923091
A19: 10.8.1.2 | B19: 40662 | C19: =DATEDIF(B19,B20,"d") -> 178 | D19: 613782 | E19: 4134 | F19: =E19/D19 -> 0.0067352904
A20: 10.8.2.2 | B20: 40840 | C20: =DATEDIF(B20,B21,"d") -> 389 | D20: 617878 | E20: 1649 | F20: =E20/D20 -> 0.0026688116
A21: 10.8.3.0 | B21: 41229 | D21: 629118 | E21: 1213 | F21: =E21/D21 -> 0.0019280962
A22: 10.9.1.0 | B22: 41085 | C22: =DATEDIF(B22,B23,"d") -> 294 | D22: 631499 | E22: 14020 | F22: =E22/D22 -> 0.022201144
A23: 10.10.1.1 | B23: 41379 | C23: =DATEDIF(B23,B24,"d") -> 365 | D23: 645880 | E23: 29985 | F23: =E23/D23 -> 0.046425033
A24: 10.10.2.0 | B24: 41744 | C24: =DATEDIF(B24,B25,"d") -> 133 | D24: 648173 | E24: 1957 | F24: =E24/D24 -> 0.0030192557
A25: 10.11.1.1 | B25: 41877 | C25: =DATEDIF(B25,B26,"d") -> 411 | D25: 674714 | E25: 37526 | F25: =E25/D25 -> 0.055617639
A26: 10.12.1.1 | B26: 42288 | C26: =DATEDIF(B26,B27,"d") -> 380 | D26: 687165 | E26: 4062 | F26: =E26/D26 -> 0.005911244
A27: 10.13.1.1 | B27: 42668 | C27: =DATEDIF(B27,B28,"d") -> 555 | D27: 688376 | E27: 5038 | F27: =E27/D27 -> 0.0073186747
A28: 10.14.2.0 | B28: 43223 | D28: 689306 | E28: 8432 | F28: =E28/D28 -> 0.012232593
D29: =SUM(D6:D28) -> 13202074

Sheet Karaf
C1: DateDiff | D1: Code | E1: CodeDiff | F1: Ratio(CodeDiff/Code)
B2: Average | C2: =AVERAGE(C7:C38) -> 117 | D2: =AVERAGE(D7:D38) -> 90999.844 | E2: =AVERAGE(E7:E38) -> 1747.4 | F2: =AVERAGE(F7:F38) -> 0.01994631
B3: Median | C3: =MEDIAN(C7:C38) -> 110 | D3: =MEDIAN(D7:D38) -> 98398 | E3: =MEDIAN(E7:E38) -> 1019.5 | F3: =MEDIAN(F7:F38) -> 0.011433664
B4: Stdev | C4: =STDEV(C7:C38) -> 98.257786 | D4: =STDEV(D7:D38) -> 16916.966 | E4: =STDEV(E7:E38) -> 2222.6546 | F4: =STDEV(F7:F38) -> 0.025039962
A5: Version | B5: Start_Date
A6: 2.4.4 | B6: 42390 | D6: 60978
A7: 3.0.0 | B7: 41629 | C7: =DATEDIF(B7,B8,"d") -> 110 | D7: 63186 | E7: 6290 | F7: =E7/D7 -> 0.099547368
A8: 3.0.1 | B8: 41739 | C8: =DATEDIF(B8,B9,"d") -> 183 | D8: 64721 | E8: 2416 | F8: =E8/D8 -> 0.03732946
A9: 3.0.2 | B9: 41922 | C9: =DATEDIF(B9,B10,"d") -> 110 | D9: 66931 | E9: 1944 | F9: =E9/D9 -> 0.029044837
A10: 3.0.3 | B10: 42032 | C10: =DATEDIF(B10,B11,"d") -> 152 | D10: 67967 | E10: 1158 | F10: =E10/D10 -> 0.01703768
A11: 3.0.4 | B11: 42184 | C11: =DATEDIF(B11,B12,"d") -> 95 | D11: 68402 | E11: 1146 | F11: =E11/D11 -> 0.016753896
A12: 3.0.5 | B12: 42279 | C12: =DATEDIF(B12,B13,"d") -> 130 | D12: 68413 | E12: 639 | F12: =E12/D12 -> 0.0093403301
A13: 3.0.6 | B13: 42409 | C13: =DATEDIF(B13,B14,"d") -> 126 | D13: 68979 | E13: 1045 | F13: =E13/D13 -> 0.015149538
A14: 3.0.7 | B14: 42535 | C14: =DATEDIF(B14,B15,"d") -> 55 | D14: 69478 | E14: 624 | F14: =E14/D14 -> 0.0089812603
A15: 3.0.8 | B15: 42590 | C15: =DATEDIF(B15,B16,"d") -> 567 | D15: 69713 | E15: 496 | F15: =E15/D15 -> 0.0071148853
A16: 3.0.9 | B16: 43157 | D16: 69710 | E16: 472 | F16: =E16/D16 -> 0.006770908
A17: 4.0.0 | B17: 42178 | C17: =DATEDIF(B17,B18,"d") -> 54 | D17: 94073 | E17: 8651 | F17: =E17/D17 -> 0.091960499
A18: 4.0.1 | B18: 42232 | C18: =DATEDIF(B18,B19,"d") -> 54 | D18: 94767 | E18: 1222 | F18: =E18/D18 -> 0.012894784
A19: 4.0.2 | B19: 42286 | C19: =DATEDIF(B19,B20,"d") -> 29 | D19: 95510 | E19: 876 | F19: =E19/D19 -> 0.0091718145
A20: 4.0.3 | B20: 42315 | C20: =DATEDIF(B20,B21,"d") -> 64 | D20: 95724 | E20: 524 | F20: =E20/D20 -> 0.0054740713
A21: 4.0.4 | B21: 42379 | C21: =DATEDIF(B21,B22,"d") -> 99 | D21: 97285 | E21: 1382 | F21: =E21/D21 -> 0.014205684
A22: 4.0.5 | B22: 42478 | C22: =DATEDIF(B22,B23,"d") -> 127 | D22: 97986 | E22: 1421 | F22: =E22/D22 -> 0.014502072
A23: 4.0.6 | B23: 42605 | C23: =DATEDIF(B23,B24,"d") -> 27 | D23: 99540 | E23: 1374 | F23: =E23/D23 -> 0.013803496
A24: 4.0.7 | B24: 42632 | C24: =DATEDIF(B24,B25,"d") -> 86 | D24: 99750 | E24: 444 | F24: =E24/D24 -> 0.0044511278
A25: 4.0.8 | B25: 42718 | C25: =DATEDIF(B25,B26,"d") -> 113 | D25: 100557 | E25: 698 | F25: =E25/D25 -> 0.0069413368
A26: 4.0.9 | B26: 42831 | C26: =DATEDIF(B26,B27,"d") -> 170 | D26: 101054 | E26: 756 | F26: =E26/D26 -> 0.0074811487
A27: 4.0.10 | B27: 43001 | D27: 101315
A28: 4.1.0 | B28: 42767 | C28: =DATEDIF(B28,B29,"d") -> 55 | D28: 98939
A29: 4.1.1 | B29: 42822 | C29: =DATEDIF(B29,B30,"d") -> 129 | D29: 98810 | E29: 994 | F29: =E29/D29 -> 0.010059711
A30: 4.1.2 | B30: 42951 | C30: =DATEDIF(B30,B31,"d") -> 83 | D30: 100141 | E30: 1558 | F30: =E30/D30 -> 0.015558063
A31: 4.1.3 | B31: 43034 | C31: =DATEDIF(B31,B32,"d") -> 50 | D31: 100532 | E31: 762 | F31: =E31/D31 -> 0.0075796761
A32: 4.1.4 | B32: 43084 | C32: =DATEDIF(B32,B33,"d") -> 59 | D32: 101239 | E32: 694 | F32: =E32/D32 -> 0.0068550657
A33: 4.1.5 | B33: 43143 | C33: =DATEDIF(B33,B34,"d") -> 178 | D33: 101478 | E33: 564 | F33: =E33/D33 -> 0.0055578549
A34: 4.1.6 | B34: 43321 | C34: =DATEDIF(B34,B35,"d") -> 112 | D34: 102161 | E34: 709 | F34: =E34/D34 -> 0.006940026
A35: 4.1.7 | B35: 43433 | D35: 102436 | E35: 426 | F35: =E35/D35 -> 0.0041586942
A36: 4.2.0 | B36: 43195 | C36: =DATEDIF(B36,B37,"d") -> 135 | D36: 114343 | E36: 9047 | F36: =E36/D36 -> 0.07912159
A37: 4.2.1 | B37: 43330 | C37: =DATEDIF(B37,B38,"d") -> 124 | D37: 117551 | E37: 2562 | F37: =E37/D37 -> 0.021794795
A38: 4.2.2 | B38: 43454 | D38: 119304 | E38: 1528 | F38: =E38/D38 -> 0.012807618
D39: =SUM(D17:D38) -> 2234495

Sheet Cassandra
C1: DateDiff | D1: Code | E1: CodeDiff | F1: Ratio(CodeDiff/Code)
B2: Average | C2: =AVERAGE(C3:C33) -> 51.901578 | D2: =AVERAGE(D6:D34) -> 192726.5 | E2: =AVERAGE(E7:E34) -> 4450.75 | F2: =AVERAGE(F7:F34) -> 0.022970612
B3: Median | C3: =MEDIAN(C6:C33) -> 34 | D3: =MEDIAN(D6:D34) -> 188703 | E3: =MEDIAN(E7:E34) -> 3116 | F3: =MEDIAN(F7:F34) -> 0.016619017
B4: Stdev | C4: =STDEV(C6:C33) -> 52.145752 | D4: =STDEV(D6:D34) -> 11108.373 | E4: =STDEV(E7:E34) -> 3614.7663 | F4: =STDEV(F7:F34) -> 0.018136829
A5: Version | B5: Start_Date
A6: 3.0.0 | B6: 11/9/2015 | C6: =DATEDIF(B6,B7,"d") -> 29
A7: 3.0.1 | B7: 12/8/2015 | C7: =DATEDIF(B7,B8,"d") -> 13 | D7: 182194 | E7: 2595 | F7: =E7/D7 -> 0.01424306
A8: 3.0.2 | B8: 12/21/2015 | C8: =DATEDIF(B8,B9,"d") -> 50 | D8: 182197 | E8: 2416 | F8: =E8/D8 -> 0.013260372
A9: 3.0.3 | B9: 2/9/2016 | C9: =DATEDIF(B9,B10,"d") -> 28 | D9: 183589 | E9: 3665 | F9: =E9/D9 -> 0.01996307
A10: 3.0.4 | B10: 3/8/2016 | C10: =DATEDIF(B10,B11,"d") -> 34 | D10: 184524 | E10: 3069 | F10: =E10/D10 -> 0.016631983
A11: 3.0.5 | B11: 4/11/2016 | C11: =DATEDIF(B11,B12,"d") -> 32 | D11: 185361 | E11: 2906 | F11: =E11/D11 -> 0.015677516
A12: 3.0.6 | B12: 5/13/2016 | C12: =DATEDIF(B12,B13,"d") -> 31 | D12: 185595 | E12: 3082 | F12: =E12/D12 -> 0.016606051
A13: 3.0.7 | B13: 6/13/2016 | C13: =DATEDIF(B13,B14,"d") -> 22 | D13: 186003 | E13: 3245 | F13: =E13/D13 -> 0.017445955
A14: 3.0.8 | B14: 7/5/2016 | C14: =DATEDIF(B14,B15,"d") -> 76 | D14: 186499 | E14: 2768 | F14: =E14/D14 -> 0.014841903
A15: 3.0.9 | B15: 9/19/2016 | C15: =DATEDIF(B15,B16,"d") -> 58 | D15: 188007 | E15: 4123 | F15: =E15/D15 -> 0.021930035
A16: 3.0.10 | B16: 11/16/2016 | C16: =DATEDIF(B16,B17,"d") -> 97 | D16: 188438 | E16: 15060 | F16: =E16/D16 -> 0.079920186
A17: 3.0.11 | B17: 2/21/2017 | C17: =DATEDIF(B17,B18,"d") -> 17 | D17: 188968 | E17: 3268 | F17: =E17/D17 -> 0.017293933
A18: 3.0.12 | B18: 3/10/2017 | C18: =DATEDIF(B18,B19,"d") -> 35 | D18: 189293 | E18: 2594 | F18: =E18/D18 -> 0.013703623
... A22: 3.0.16 | B22: 5/4/2018 | C22: =DATEDIF(B22,B23,"d") -> 89 | D22: 193146 | E22: 2954 | F22: =E22/D22 -> 0.01529413
A23: 3.0.17 | B23: 8/1/2018 | D23: 193702 | E23: 2954 | F23: =E23/D23 -> 0.01525023
A24: 3.1 | B24: 12/8/2015 | C24: =DATEDIF(B24,B25,"d") -> 34 | D24: 182194 | E24: 12172 | F24: =E24/D24 -> 0.066807908
A25: 3.2 | B25: 1/11/2016 | C25: =DATEDIF(B25,B26,"d") -> 8 | D25: 185590 | E25: 6400 | F25: =E25/D25 -> 0.034484617
A26: 3.2.1 | B26: 1/19/2016 | C26: =DATEDIF(B26,B27,"d") -> 21 | D26: 185561 | E26: 2414 | F26: =E26/D26 -> 0.013009199
A27: 3.3 | B27: 2/9/2016 | C27: =DATEDIF(B27,B28,"d") -> 28 | D27: 186376 | E27: 3181 | F27: =E27/D27 -> 0.017067648
A28: 3.4 | B28: 3/8/2016 | C28: =DATEDIF(B28,B29,"d") -> 36 | D28: 200380 | E28: 6477 | F28: =E28/D28 -> 0.032323585
A29: 3.5 | B29: 4/13/2016 | C29: =DATEDIF(B29,B30,"d") -> 54 | D29: 201450 | E29: 3150 | F29: =E29/D29 -> 0.015636634
A30: 3.6 | B30: 6/6/2016 | C30: =DATEDIF(B30,B31,"d") -> 7 | D30: 207961 | E30: 4689 | F30: =E30/D30 -> 0.022547497
A31: 3.7 | B31: 6/13/2016 | C31: =DATEDIF(B31,B32,"d") -> 108 | D31: 208401 | E31: 906 | F31: =E31/D31 -> 0.004347388
A32: 3.8 | B32: 9/29/2016 | C32: =DATEDIF(B32,B33,"d") -> 0 | D32: 211511 | E32: 7115 | F32: =E32/D32 -> 0.033638912
A33: 3.9 | B33: 9/29/2016 | C33: =DATEDIF(B33,B34,"d") -> 127 | D33: 211511 | E33: 22 | F33: =E33/D33 -> 0.0001040135
A34: 3.10 | B34: 2/3/2017 | C34: =DATEDIF(B34,B35,"d") -> 243 | D34: 226085 | E34: 14037 | F34: =E34/D34 -> 0.062087268
A35: 3.11.0 | B35: 10/4/2017 | C35: =DATEDIF(B35,B36,"d") -> 212 | D35: 199685 | E35: 1313 | F35: =E35/D35 -> 0.0065753562
A36: 3.11.1 | B36: 5/4/2018 | C36: =DATEDIF(B36,B37,"d") -> 0 | D36: 202170 | E36: 1491 | F36: =E36/D36 -> 0.0073749815
A37: 3.11.2 | B37: 5/4/2018 | C37: =DATEDIF(B37,B38,"d") -> 89 | D37: 203417 | E37: 1075 | F37: =E37/D37 -> 0.0052847107
A38: 3.11.3 | B38: 8/1/2018 | D38: 204154 | E38: 554 | F38: =E38/D38 -> 0.0027136377

Sheet HBase
D1: Code | E1: CodeDiff | F1: Ratio(CodeDiff/Code)
B2: Average | D2: =AVERAGE(D6:D14) -> 720112.56 | E2: =AVERAGE(E7:E14) -> 28109 | F2: =AVERAGE(F7:F14) -> 0.038235093
B3: Median | D3: =MEDIAN(D6:D14) -> 673394 | E3: =MEDIAN(E7:E14) -> 12070.5 | F3: =MEDIAN(F7:F14) -> 0.017006672
B4: Stdev | D4: =STDEV(D6:D14) -> 73608.902 | E4: =STDEV(E7:E14) -> 32920.251 | F4: =STDEV(F7:F14) -> 0.046654063
A5: Version | B5: Start_Date
A6: 1.0.0 | B6: 2/21/2015 | D6: 661051
A7: 1.0.1 | B7: 4/28/2015 | D7: 665253 | E7: 2703 | F7: =E7/D7 -> 0.0040631158
A8: 1.0.3 | B8: 5/9/2016 | D8: 673394 | E8: 5213 | F8: =E8/D8 -> 0.0077413817
A9: 1.1.0 | B9: 5/14/2015 | D9: 728989 | E9: 17118 | F9: =E9/D9 -> 0.023481836
A10: 1.2.8 | B10: 10/20/2018 | D10: 780781 | E10: 40834 | F10: =E10/D10 -> 0.052298916
A11: 1.2.9 | B11: 11/27/2018 | D11: 780848 | E11: 147 | F11: =E11/D11 -> 0.00018825687
A12: 1.4.9 | B12: 12/14/2018 | D12: 864110 | E12: 62954 | F12: =E12/D12 -> 0.072854151
A13: 2.0.3 | B13: 12/3/2018 | D13: 659731 | E13: 88880 | F13: =E13/D13 -> 0.13472158
A14: 2.1.1 | B14: 10/31/2018 | D14: 666856 | E14: 7023 | F14: =E14/D14 -> 0.010531509

Sheet XNIO
C1: DateDiff | D1: Code | E1: CodeDiff | F1: Ratio(CodeDiff/Code)
B2: Average | C2: =AVERAGE(C6:C174) -> 161.8 | D2: =AVERAGE(D6:D34) -> 8552.5714 | E2: =AVERAGE(E7:E34) -> 357.4 | F2: =AVERAGE(F7:F34) -> 0.069266324
B3: Median | C3: =MEDIAN(C6:C174) -> 37 | D3: =MEDIAN(D6:D34) -> 5286 | E3: =MEDIAN(E7:E34) -> 374 | F3: =MEDIAN(F7:F34) -> 0.049365629
B4: Stdev | C4: =STDEV(C6:C174) -> 307.72504 | D4: =STDEV(D6:D34) -> 9659.4123 | E4: =STDEV(E7:E34) -> 320.24491 | F4: =STDEV(F7:F34) -> 0.064875012
A5: Version | B5: Start_Date
A6: 1.1.0 | B6: 40105 | C6: =DATEDIF(B6,B7,"d") -> 0 | D6: 1854
A7: 1.2.0 | B7: 40105 | C7: =DATEDIF(B7,B8,"d") -> 37 | D7: 3356 | E7: 374 | F7: =E7/D7 -> 0.11144219
A8: 2.0.0 | B8: 40142 | C8: =DATEDIF(B8,B9,"d") -> 9 | D8: 5282 | E8: 841 | F8: =E8/D8 -> 0.15921999
A9: 2.0.1 | B9: 40151 | C9: =DATEDIF(B9,B10,"d") -> 52 | D9: 5286 | E9: 8 | F9: =E9/D9 -> 0.0015134317
A10: 2.0.2 | B10: 40203 | C10: =DATEDIF(B10,B11,"d") -> 711 | D10: 5486 | E10: 136 | F10: =E10/D10 -> 0.024790376
A11: 3.0.0 | B11: 40914 | D11: 8670 | E11: 428 | F11: =E11/D11 -> 0.049365629
D12: =SUM(D6:D11) -> 29934
