Workbook

Sheet OverAll
C1: #SOC | D1: DateDiff | E1: Ratio
B2: Average | D2: =AVERAGE(D6:D14) -> 128.53666 | E2: =AVERAGE(E6:E14) -> 0.0064607022
B3: Median | D3: =MEDIAN(D6:D14) -> 117 | E3: =MEDIAN(E6:E14) -> 0.0012857165
B4: Stdev | D4: =STDEV(D6:D14) -> 97.437905 | E4: =STDEV(E6:E14) -> 0.010494334
A5: Subject
A6: OpenChord | C6: 8299.1667 | D6: =OpenChord!C2 -> 201.6 | E6: =D6/C6 -> 0.024291596
A7: Thrift | C7: 10773.429 | D7: =Thrift!C2 -> 274 | E7: =D7/C7 -> 0.025432943
A8: xSocket | C8: 12796.633 | D8: =xSocket!C2 -> 28.482759 | E8: =D8/C8 -> 0.0022258009
A9: Voldemort | C9: 103184.65 | D9: =Voldemort!C2 -> 19.1375 | E9: =D9/C9 -> 0.00018546847
A10: ZooKeeper | C10: 49683.382 | D10: =Zookeeper!C2 -> 177.03333 | E10: =D10/C10 -> 0.0035632303
A11: Netty | C11: 92949.962 | D11: =Netty!C2 -> 40.715596 | E11: =D11/C11 -> 0.00043803779
A12: Derby | C12: 574003.22 | D12: =Derby!C2 -> 240 | E12: =D12/C12 -> 0.00041811612
A13: Karaf | C13: 90999.844 | D13: =Karaf!C2 -> 117 | E13: =D13/C13 -> 0.0012857165
A14: Cassandra | C14: 192726.5 | D14: =Cassandra!C2 -> 58.860759 | E14: =D14/C14 -> 0.00030541083
A15: XNIO | C15: 4989 | D15: 161.8 | E15: =D15/C15 -> 0.032431349

Sheet OpenChord
C1: DateDiff
B2: Average | C2: =AVERAGE(C6:C10) -> 201.6
B3: Median | C3: =MEDIAN(C6:C10) -> 187
B4: Stdev | C4: =STDEV(C6:C10) -> 156.44744
A5: Version | B5: Start_Date
A6: v1.0 | B6: 38748 | C6: =DATEDIF(B6,B7,"d") -> 339
A7: v1.0.1 | B7: 39087 | C7: =DATEDIF(B7,B8,"d") -> 7
A8: v1.0.2 | B8: 39094 | C8: =DATEDIF(B8,B9,"d") -> 187
A9: v1.0.3 | B9: 39281 | C9: =DATEDIF(B9,B10,"d") -> 99
A10: v1.0.4 | B10: 39380 | C10: =DATEDIF(B10,B11,"d") -> 376
A11: v1.0.5 | B11: 39756

Sheet Thrift
C1: DateDiff | D1: #SLOC
B2: Average | C2: =AVERAGE(C15:C19) -> 274
B3: Median | C3: =MEDIAN(C15:C19) -> 301
B4: Stdev | C4: =STDEV(C15:C19) -> 134.64769
A5: Version | B5: Start_Date
A6: V0.2.0 | B6: 41672 | C6: =DATEDIF(B6,B7,"d") -> 0
A7: V0.3.0 | B7: 41672 | C7: =DATEDIF(B7,B8,"d") -> 0
A8: V0.4.0 | B8: 41672 | C8: =DATEDIF(B8,B9,"d") -> 0
A9: V0.5.0 | B9: 41672 | C9: =DATEDIF(B9,B10,"d") -> 0
A10: V0.6.0 | B10: 41672 | C10: =DATEDIF(B10,B11,"d") -> 0
A11: V0.6.1 | B11: 41672 | C11: =DATEDIF(B11,B12,"d") -> 0
A12: V0.7.0 | B12: 41672 | C12: =DATEDIF(B12,B13,"d") -> 0
A13: V0.8.0 | B13: 41672 | C13: =DATEDIF(B13,B14,"d") -> 0
A14: V0.9.0 | B14: 41672 | C14: =DATEDIF(B14,B15,"d") -> 0
A15: V0.9.1 | B15: 41672 | C15: =DATEDIF(B15,B16,"d") -> 180
A16: hier | B16: 41852 | C16: =DATEDIF(B16,B17,"d") -> 107
A17: V0.9.2 | B17: 41959 | C17: =DATEDIF(B17,B18,"d") -> 329
A18: V0.9.3 | B18: 42288 | C18: =DATEDIF(B18,B19,"d") -> 453
A19: V0.10.0 | B19: 42741 | C19: =DATEDIF(B19,B20,"d") -> 301 | D19: 14217 | E19: =C19/D19 -> 0.021171837
A20: V0.11.0 | B20: 43042 | C20: =DATEDIF(B20,B21,"d") -> 427 | D20: 14510 | E20: =C20/D20 -> 0.029427981
A21: V0.12.0 | B21: 43469

Sheet xSocket
C1: DateDiff
B2: Average | C2: =AVERAGE(C6:C65) -> 28.482759
B3: Median | C3: =MEDIAN(C6:C65) -> 15
B4: Stdev | C4: =STDEV(C6:C65) -> 34.507686
A5: Version | B5: Start_Date
A6: V0.9-beta-1 | B6: 38915 | C6: =DATEDIF(B6,B7,"d") -> 62
A7: V1.0-beta-1 | B7: 38977 | C7: =DATEDIF(B7,B8,"d") -> 87
A8: V1.0-beta-2 | B8: 39064 | C8: =DATEDIF(B8,B9,"d") -> 35
A9: V1.0-beta-3 | B9: 39099 | C9: =DATEDIF(B9,B10,"d") -> 35
A10: V1.0-beta-4 | B10: 39134 | C10: =DATEDIF(B10,B11,"d") -> 29
A11: V1.0 | B11: 39163 | C11: =DATEDIF(B11,B12,"d") -> 8
A12: V1.1 | B12: 39171 | C12: =DATEDIF(B12,B13,"d") -> 134
A13: V1.2 | B13: 39305 | C13: =DATEDIF(B13,B14,"d") -> 66
A14: V1.2.1 | B14: 39371
A15: V2.0-alpha-1 | B15: 39356 | C15: =DATEDIF(B15,B16,"d") -> 142
A16: V2.0-alpha-2 | B16: 39498 | C16: =DATEDIF(B16,B17,"d") -> 16
A17: V2.0-beta-1 | B17: 39514 | C17: =DATEDIF(B17,B18,"d") -> 11
A18: V2.0-beta-2 | B18: 39525 | C18: =DATEDIF(B18,B19,"d") -> 38
A19: V2.0 | B19: 39563 | C19: =DATEDIF(B19,B20,"d") -> 55
A20: V2.1 | B20: 39618 | C20: =DATEDIF(B20,B21,"d") -> 49
A21: V2.1.1 | B21: 39667 | C21: =DATEDIF(B21,B22,"d") -> 34
A22: V2.1.2 | B22: 39701 | C22: =DATEDIF(B22,B23,"d") -> 40
A23: V2.2 | B23: 39741 | C23: =DATEDIF(B23,B24,"d") -> 15
A24: V2.3 | B24: 39756 | C24: =DATEDIF(B24,B25,"d") -> 25
A25: V2.3.1 | B25: 39781 | C25: =DATEDIF(B25,B26,"d") -> 43
A26: V2.3.2 | B26: 39824 | C26: =DATEDIF(B26,B27,"d") -> 15
... A64: V2.8.14 | B64: 40442 | C64: =DATEDIF(B64,B65,"d") -> 110
A65: V2.8.15 | B65: 40552

Sheet Voldemort
C1: DateDiff
B2: Average | C2: =AVERAGE(C6:C86) -> 19.1375
B3: Median | C3: =MEDIAN(C6:C86) -> 11
B4: Stdev | C4: =STDEV(C6:C86) -> 31.249403
A5: Version | B5: Start_Date
A6: V1.4.0 | B6: 41446 | C6: =DATEDIF(B6,B7,"d") -> 76
A7: V1.5.1 | B7: 41522 | C7: =DATEDIF(B7,B8,"d") -> 7
A8: V1.5.2 | B8: 41529 | C8: =DATEDIF(B8,B9,"d") -> 19
A9: V1.5.4 | B9: 41548 | C9: =DATEDIF(B9,B10,"d") -> 27
A10: V1.5.7 | B10: 41575 | C10: =DATEDIF(B10,B11,"d") -> 1
A11: V1.5.8 | B11: 41576 | C11: =DATEDIF(B11,B12,"d") -> 27
A12: V1.5.9 | B12: 41603 | C12: =DATEDIF(B12,B13,"d") -> 1
A13: V1.6.0 | B13: 41604 | C13: =DATEDIF(B13,B14,"d") -> 17
A14: V1.6.1 | B14: 41621 | C14: =DATEDIF(B14,B15,"d") -> 28
A15: V1.6.2 | B15: 41649 | C15: =DATEDIF(B15,B16,"d") -> 21
A16: V1.6.3 | B16: 41670 | C16: =DATEDIF(B16,B17,"d") -> 3
A17: V1.6.4 | B17: 41673 | C17: =DATEDIF(B17,B18,"d") -> 4
... A85: V1.10.25 | B85: 42943 | C85: =DATEDIF(B85,B86,"d") -> 34
A86: V1.10.26 | B86: 42977

Sheet Zookeeper
C1: DateDiff
B2: Average | C2: =AVERAGE(C6:C38) -> 177.03333
B3: Median | C3: =MEDIAN(C6:C38) -> 154
B4: Stdev | C4: =STDEV(C6:C38) -> 150.00195
A5: Version | B5: Start_Date
A6: V3.0.0 | B6: 39748 | C6: =DATEDIF(B6,B7,"d") -> 8
A7: V3.0.1 | B7: 39756 | C7: =DATEDIF(B7,B8,"d") -> 101
A8: V3.1.0 | B8: 39857 | C8: =DATEDIF(B8,B9,"d") -> 42
A9: V3.1.1 | B9: 39899 | C9: =DATEDIF(B9,B10,"d") -> 232
A10: V3.1.2 | B10: 40131
A11: V3.2.0 | B11: 40002 | C11: =DATEDIF(B11,B12,"d") -> 58
A12: V3.2.1 | B12: 40060 | C12: =DATEDIF(B12,B13,"d") -> 0
A13: V3.2.2 | B13: 40060 | C13: =DATEDIF(B13,B14,"d") -> 202
A14: V3.3.0 | B14: 40262 | C14: =DATEDIF(B14,B15,"d") -> 53
A15: V3.3.1 | B15: 40315 | C15: =DATEDIF(B15,B16,"d") -> 178
A16: V3.3.2 | B16: 40493 | C16: =DATEDIF(B16,B17,"d") -> 108
A17: V3.3.3 | B17: 40601 | C17: =DATEDIF(B17,B18,"d") -> 272
A18: V3.3.4 | B18: 40873 | C18: =DATEDIF(B18,B19,"d") -> 115
A19: V3.3.5 | B19: 40988 | C19: =DATEDIF(B19,B20,"d") -> 135
A20: V3.3.6 | B20: 41123
A21: V3.4.0 | B21: 40869 | C21: =DATEDIF(B21,B22,"d") -> 24
A22: V3.4.1 | B22: 40893 | C22: =DATEDIF(B22,B23,"d") -> 13
A23: V3.4.2 | B23: 40906 | C23: =DATEDIF(B23,B24,"d") -> 46
A24: V3.4.3 | B24: 40952 | C24: =DATEDIF(B24,B25,"d") -> 223
A25: V3.4.4 | B25: 41175 | C25: =DATEDIF(B25,B26,"d") -> 56
A26: V3.4.5 | B26: 41231 | C26: =DATEDIF(B26,B27,"d") -> 477
A27: V3.4.6 | B27: 41708 | C27: =DATEDIF(B27,B28,"d") -> 621
A28: V3.4.7 | B28: 42329 | C28: =DATEDIF(B28,B29,"d") -> 91
A29: V3.4.8 | B29: 42420 | C29: =DATEDIF(B29,B30,"d") -> 196
A30: V3.4.9 | B30: 42616 | C30: =DATEDIF(B30,B31,"d") -> 208
A31: V3.4.10 | B31: 42824 | C31: =DATEDIF(B31,B32,"d") -> 224
A32: V3.4.11 | B32: 43048 | C32: =DATEDIF(B32,B33,"d") -> 173
A33: V3.4.12 | B33: 43221 | C33: =DATEDIF(B33,B34,"d") -> 75
A34: V3.4.13 | B34: 43296
A35: V3.5.0 | B35: 41857 | C35: =DATEDIF(B35,B36,"d") -> 390
A36: V3.5.1 | B36: 42247 | C36: =DATEDIF(B36,B37,"d") -> 324
A37: V3.5.2 | B37: 42571 | C37: =DATEDIF(B37,B38,"d") -> 271
A38: V3.5.3 | B38: 42842 | C38: =DATEDIF(B38,B39,"d") -> 395
A39: V3.5.4 | B39: 43237

Sheet Netty
C1: DateDiff
B2: Average | C2: =AVERAGE(C48:C162) -> 40.715596
B3: Median | C3: =MEDIAN(C48:C162) -> 31
B4: Stdev | C4: =STDEV(C48:C162) -> 42.470925
A5: Version | B5: Start_Date
A6: 3.1.0 | B6: 41448 | C6: =DATEDIF(B6,B7,"d") -> 4
A7: 3.1.1 | B7: 41452 | C7: =DATEDIF(B7,B8,"d") -> 0
A8: 3.1.2 | B8: 41452 | C8: =DATEDIF(B8,B9,"d") -> 0
A9: 3.1.3 | B9: 41452 | C9: =DATEDIF(B9,B10,"d") -> 0
A10: 3.1.4 | B10: 41452 | C10: =DATEDIF(B10,B11,"d") -> 0
A11: 3.1.5 | B11: 41452
A12: 3.2.0 | B12: 41448 | C12: =DATEDIF(B12,B13,"d") -> 4
A13: 3.2.1 | B13: 41452 | C13: =DATEDIF(B13,B14,"d") -> 0
A14: 3.2.2 | B14: 41452 | C14: =DATEDIF(B14,B15,"d") -> 0
A15: 3.2.3 | B15: 41452 | C15: =DATEDIF(B15,B16,"d") -> 0
A16: 3.2.4 | B16: 41452 | C16: =DATEDIF(B16,B17,"d") -> 0
A17: 3.2.5 | B17: 41452 | C17: =DATEDIF(B17,B18,"d") -> 0
A18: 3.2.6 | B18: 41452 | C18: =DATEDIF(B18,B19,"d") -> 0
A19: 3.2.7 | B19: 41452 | C19: =DATEDIF(B19,B20,"d") -> 0
A20: 3.3.0 | B20: 41452 | C20: =DATEDIF(B20,B21,"d") -> 0
A21: 3.3.1 | B21: 41452 | C21: =DATEDIF(B21,B22,"d") -> 0
A22: 3.4.0 | B22: 41452 | C22: =DATEDIF(B22,B23,"d") -> 0
A23: 3.4.1 | B23: 41452 | C23: =DATEDIF(B23,B24,"d") -> 0
... A51: 3.6.8 | B51: 41710 | C51: =DATEDIF(B51,B52,"d") -> 49
A52: 3.6.9 | B52: 41759
A53: 3.7.0 | B53: 41522 | C53: =DATEDIF(B53,B54,"d") -> 237
A54: 3.7.1 | B54: 41759
A55: 3.8.0 | B55: 41585 | C55: =DATEDIF(B55,B56,"d") -> 174
A56: 3.8.2 | B56: 41759
A57: 3.9.0 | B57: 41630 | C57: =DATEDIF(B57,B58,"d") -> 129
A58: 3.9.1 | B58: 41759 | C58: =DATEDIF(B58,B59,"d") -> 42
A59: 3.9.2 | B59: 41801 | C59: =DATEDIF(B59,B60,"d") -> 56
A60: 3.9.3 | B60: 41857 | C60: =DATEDIF(B60,B61,"d") -> 20
A61: 3.9.4 | B61: 41877 | C61: =DATEDIF(B61,B62,"d") -> 65
A62: 3.9.5 | B62: 41942 | C62: =DATEDIF(B62,B63,"d") -> 48
A63: 3.9.6 | B63: 41990 | C63: =DATEDIF(B63,B64,"d") -> 81
A64: 3.9.7 | B64: 42071 | C64: =DATEDIF(B64,B65,"d") -> 61
A65: 3.9.8 | B65: 42132 | C65: =DATEDIF(B65,B66,"d") -> 74
A66: 3.9.9 | B66: 42206
A67: 3.10.0 | B67: 41990 | C67: =DATEDIF(B67,B68,"d") -> 96
...

Sheet Derby
C1: DateDiff
B2: Average | C2: =AVERAGE(C6:C26) -> 240
B3: Median | C3: =MEDIAN(C6:C26) -> 206
B4: Stdev | C4: =STDEV(C6:C26) -> 151.17783
A5: Version | B5: Start_Date
A6: 10.1.1.0 | B6: 38567 | C6: =DATEDIF(B6,B7,"d") -> 97
A7: 10.1.2.1 | B7: 38664 | C7: =DATEDIF(B7,B8,"d") -> 234
A8: 10.1.3.1 | B8: 38898 | C8: =DATEDIF(B8,B9,"d") -> 165
A9: 10.2.2.0 | B9: 39063 | C9: =DATEDIF(B9,B10,"d") -> 499
A10: 10.4.1.3 | B10: 39562 | C10: =DATEDIF(B10,B11,"d") -> 18
A11: 10.3.3.0 | B11: 39580 | C11: =DATEDIF(B11,B12,"d") -> 116
A12: 10.4.2.0 | B12: 39696 | C12: =DATEDIF(B12,B13,"d") -> 235
A13: 10.5.1.1 | B13: 39931 | C13: =DATEDIF(B13,B14,"d") -> 115
A14: 10.5.3.0 | B14: 40046 | C14: =DATEDIF(B14,B15,"d") -> 271
A15: 10.6.1.0 | B15: 40317 | C15: =DATEDIF(B15,B16,"d") -> 139
A16: 10.6.2.1 | B16: 40456 | C16: =DATEDIF(B16,B17,"d") -> 40
A17: 10.7.1.1 | B17: 40496 | C17: =DATEDIF(B17,B18,"d") -> 166
... A19: 10.8.2.2 | B19: 40840 | C19: =DATEDIF(B19,B20,"d") -> 389
A20: 10.8.3.0 | B20: 41229
A21: 10.9.1.0 | B21: 41085 | C21: =DATEDIF(B21,B22,"d") -> 294
A22: 10.10.1.1 | B22: 41379 | C22: =DATEDIF(B22,B23,"d") -> 365
A23: 10.10.2.0 | B23: 41744 | C23: =DATEDIF(B23,B24,"d") -> 133
A24: 10.11.1.1 | B24: 41877 | C24: =DATEDIF(B24,B25,"d") -> 411
A25: 10.12.1.1 | B25: 42288 | C25: =DATEDIF(B25,B26,"d") -> 380
A26: 10.13.1.1 | B26: 42668 | C26: =DATEDIF(B26,B27,"d") -> 555
A27: 10.24.2.0 | B27: 43223

Sheet Karaf
C1: DateDiff
B2: Average | C2: =AVERAGE(C6:C36) -> 117
B3: Median | C3: =MEDIAN(C6:C36) -> 110
B4: Stdev | C4: =STDEV(C6:C36) -> 98.257786
A5: Version | B5: Start_Date
A6: 3.0.0 | B6: 41629 | C6: =DATEDIF(B6,B7,"d") -> 110
A7: 3.0.1 | B7: 41739 | C7: =DATEDIF(B7,B8,"d") -> 183
A8: 3.0.2 | B8: 41922 | C8: =DATEDIF(B8,B9,"d") -> 110
A9: 3.0.3 | B9: 42032 | C9: =DATEDIF(B9,B10,"d") -> 152
A10: 3.0.4 | B10: 42184 | C10: =DATEDIF(B10,B11,"d") -> 95
A11: 3.0.5 | B11: 42279 | C11: =DATEDIF(B11,B12,"d") -> 130
A12: 3.0.6 | B12: 42409 | C12: =DATEDIF(B12,B13,"d") -> 126
A13: 3.0.7 | B13: 42535 | C13: =DATEDIF(B13,B14,"d") -> 55
A14: 3.0.8 | B14: 42590 | C14: =DATEDIF(B14,B15,"d") -> 567
A15: 3.0.9 | B15: 43157
A16: 4.0.0 | B16: 42178 | C16: =DATEDIF(B16,B17,"d") -> 54
A17: 4.0.1 | B17: 42232 | C17: =DATEDIF(B17,B18,"d") -> 54
A18: 4.0.2 | B18: 42286 | C18: =DATEDIF(B18,B19,"d") -> 29
A19: 4.0.3 | B19: 42315 | C19: =DATEDIF(B19,B20,"d") -> 64
A20: 4.0.4 | B20: 42379 | C20: =DATEDIF(B20,B21,"d") -> 99
A21: 4.0.5 | B21: 42478 | C21: =DATEDIF(B21,B22,"d") -> 127
A22: 4.0.6 | B22: 42605 | C22: =DATEDIF(B22,B23,"d") -> 27
A23: 4.0.7 | B23: 42632 | C23: =DATEDIF(B23,B24,"d") -> 86
A24: 4.0.8 | B24: 42718 | C24: =DATEDIF(B24,B25,"d") -> 113
A25: 4.0.9 | B25: 42831 | C25: =DATEDIF(B25,B26,"d") -> 170
A26: 4.0.10 | B26: 43001
A27: 4.1.0 | B27: 42767 | C27: =DATEDIF(B27,B28,"d") -> 55
A28: 4.1.1 | B28: 42822 | C28: =DATEDIF(B28,B29,"d") -> 129
A29: 4.1.2 | B29: 42951 | C29: =DATEDIF(B29,B30,"d") -> 83
A30: 4.1.3 | B30: 43034 | C30: =DATEDIF(B30,B31,"d") -> 50
A31: 4.1.4 | B31: 43084 | C31: =DATEDIF(B31,B32,"d") -> 59
A32: 4.1.5 | B32: 43143 | C32: =DATEDIF(B32,B33,"d") -> 178
A33: 4.1.6 | B33: 43321 | C33: =DATEDIF(B33,B34,"d") -> 112
A34: 4.1.7 | B34: 43433
A35: 4.2.0 | B35: 43195 | C35: =DATEDIF(B35,B36,"d") -> 135
A36: 4.2.1 | B36: 43330 | C36: =DATEDIF(B36,B37,"d") -> 124
A37: 4.2.2 | B37: 43454

Sheet Cassandra
C1: DateDiff
B2: Average | C2: =AVERAGE(C6:C174) -> 58.860759
B3: Median | C3: =MEDIAN(C6:C174) -> 34.5
B4: Stdev | C4: =STDEV(C6:C174) -> 88.016318
A5: Version | B5: Start_Date
A6: 0.3.0 | B6: 7/20/2009 | C6: =DATEDIF(B6,B7,"d") -> 68
A7: 0.4.0 | B7: 9/26/2009 | C7: =DATEDIF(B7,B8,"d") -> 20
A8: 0.4.1 | B8: 10/16/2009 | C8: =DATEDIF(B8,B9,"d") -> 24
A9: 0.4.2 | B9: 11/9/2009 | C9: =DATEDIF(B9,B10,"d") -> 75
A10: 0.5.0 | B10: 1/23/2010 | C10: =DATEDIF(B10,B11,"d") -> 34
A11: 0.5.1 | B11: 2/26/2010 | C11: =DATEDIF(B11,B12,"d") -> 51
A12: 0.6.0 | B12: 4/18/2010 | C12: =DATEDIF(B12,B13,"d") -> 1
A13: 0.6.1 | B13: 4/19/2010 | C13: =DATEDIF(B13,B14,"d") -> 39
A14: 0.6.2 | B14: 5/28/2010 | C14: =DATEDIF(B14,B15,"d") -> 32
A15: 0.6.3 | B15: 6/29/2010 | C15: =DATEDIF(B15,B16,"d") -> 32
A16: 0.6.4 | B16: 7/31/2010 | C16: =DATEDIF(B16,B17,"d") -> 27
A17: 0.6.5 | B17: 8/27/2010 | C17: =DATEDIF(B17,B18,"d") -> 48
... A24: 0.6.12 | B24: 2/21/2011 | C24: =DATEDIF(B24,B25,"d") -> 56
A25: 0.6.13 | B25: 4/18/2011
A26: 0.7.0 | B26: 1/10/2011 | C26: =DATEDIF(B26,B27,"d") -> 35
A27: 0.7.1 | B27: 2/14/2011 | C27: =DATEDIF(B27,B28,"d") -> 2
A28: 0.7.2 | B28: 2/16/2011 | C28: =DATEDIF(B28,B29,"d") -> 16
A29: 0.7.3 | B29: 3/4/2011 | C29: =DATEDIF(B29,B30,"d") -> 11
A30: 0.7.4 | B30: 3/15/2011 | C30: =DATEDIF(B30,B31,"d") -> 43
A31: 0.7.5 | B31: 4/27/2011 | C31: =DATEDIF(B31,B32,"d") -> 23
A32: 0.7.6 | B32: 5/20/2011 | C32: =DATEDIF(B32,B33,"d") -> 57
A33: 0.7.7 | B33: 7/16/2011 | C33: =DATEDIF(B33,B34,"d") -> 6
A34: 0.7.8 | B34: 7/22/2011 | C34: =DATEDIF(B34,B35,"d") -> 45
A35: 0.7.9 | B35: 9/5/2011 | C35: =DATEDIF(B35,B36,"d") -> 701
A36: 0.7.10 | B36: 8/6/2013
A37: 0.8.0 | B37: 6/2/2011 | C37: =DATEDIF(B37,B38,"d") -> 26
A38: 0.8.1 | B38: 6/28/2011 | C38: =DATEDIF(B38,B39,"d") -> 28
A39: 0.8.2 | B39: 7/26/2011 | C39: =DATEDIF(B39,B40,"d") -> 13
A40: 0.8.3 | B40: 8/8/2011 | C40: =DATEDIF(B40,B41,"d") -> 3
A41: 0.8.4 | B41: 8/11/2011 | C41: =DATEDIF(B41,B42,"d") -> 28
A42: 0.8.5 | B42: 9/8/2011 | C42: =DATEDIF(B42,B43,"d") -> 12
A43: 0.8.6 | B43: 9/20/2011 | C43: =DATEDIF(B43,B44,"d") -> 20
A44: 0.8.7 | B44: 10/10/2011 | C44: =DATEDIF(B44,B45,"d") -> 53
A45: 0.8.8 | B45: 12/2/2011 | C45: =DATEDIF(B45,B46,"d") -> 12
A46: 0.8.9 | B46: 12/14/2011 | C46: =DATEDIF(B46,B47,"d") -> 601
...

Sheet HBase
C1: DateDiff
B2: Average | C2: =AVERAGE(C6:C126) -> 70.886792
B3: Median | C3: =MEDIAN(C6:C126) -> 47
B4: Stdev | C4: =STDEV(C6:C126) -> 81.681299
A5: Version | B5: Start_Date
A6: 0.20.5 | B6: 6/24/2010 | C6: =DATEDIF(B6,B7,"d") -> 36
A7: 0.20.6 | B7: 7/30/2010
A8: 0.90.0 | B8: 6/23/2013
A9: 0.90.1 | B9: 2/15/2011 | C9: =DATEDIF(B9,B10,"d") -> 40
A10: 0.90.2 | B10: 3/27/2011 | C10: =DATEDIF(B10,B11,"d") -> 53
A11: 0.90.3 | B11: 5/19/2011 | C11: =DATEDIF(B11,B12,"d") -> 66
A12: 0.90.4 | B12: 7/24/2011 | C12: =DATEDIF(B12,B13,"d") -> 152
A13: 0.90.5 | B13: 12/23/2011 | C13: =DATEDIF(B13,B14,"d") -> 84
A14: 0.90.6 | B14: 3/16/2012
A15: 0.92.0 | B15: 1/23/2012 | C15: =DATEDIF(B15,B16,"d") -> 56
A16: 0.92.1 | B16: 3/19/2012 | C16: =DATEDIF(B16,B17,"d") -> 177
A17: 0.92.2 | B17: 9/12/2012
A18: 0.94.0 | B18: 5/15/2012 | C18: =DATEDIF(B18,B19,"d") -> 85
A19: 0.94.1 | B19: 8/8/2012 | C19: =DATEDIF(B19,B20,"d") -> 65
A20: 0.94.2 | B20: 10/12/2012 | C20: =DATEDIF(B20,B21,"d") -> 52
A21: 0.94.3 | B21: 12/3/2012 | C21: =DATEDIF(B21,B22,"d") -> 40
A22: 0.94.4 | B22: 1/12/2013 | C22: =DATEDIF(B22,B23,"d") -> 34
A23: 0.94.5 | B23: 2/15/2013 | C23: =DATEDIF(B23,B24,"d") -> 36
A24: 0.94.6 | B24: 3/23/2013 | C24: =DATEDIF(B24,B25,"d") -> 33
A25: 0.94.7 | B25: 4/25/2013 | C25: =DATEDIF(B25,B26,"d") -> 37
A26: 0.94.8 | B26: 6/1/2013 | C26: =DATEDIF(B26,B27,"d") -> 33
A27: 0.94.9 | B27: 7/4/2013 | C27: =DATEDIF(B27,B28,"d") -> 20
A28: 0.94.10 | B28: 7/24/2013 | C28: =DATEDIF(B28,B29,"d") -> 27
A29: 0.94.11 | B29: 8/20/2013 | C29: =DATEDIF(B29,B30,"d") -> 35
... A44: 0.94.26 | B44: 12/28/2014 | C44: =DATEDIF(B44,B45,"d") -> 88
A45: 0.94.27 | B45: 3/26/2015
A46: 0.95.0 | B46: 4/7/2013 | C46: =DATEDIF(B46,B47,"d") -> 60
A47: 0.95.1 | B47: 6/6/2013 | C47: =DATEDIF(B47,B48,"d") -> 70
A48: 0.95.2 | B48: 8/15/2013 | C48: =DATEDIF(B48,B49,"d") -> 57
A49: 0.96.0 | B49: 10/11/2013 | C49: =DATEDIF(B49,B50,"d") -> 66
A50: 0.96.1 | B50: 12/16/2013 | C50: =DATEDIF(B50,B51,"d") -> 335
A51: 0.96.2 | B51: 11/16/2014
A52: 0.98.0 | B52: 2/7/2014 | C52: =DATEDIF(B52,B53,"d") -> 51
A53: 0.98.1 | B53: 3/30/2014 | C53: =DATEDIF(B53,B54,"d") -> 32
A54: 0.98.2 | B54: 5/1/2014 | C54: =DATEDIF(B54,B55,"d") -> 31
...

Sheet XNIO
C1: DateDiff
B2: Average | C2: =AVERAGE(C6:C174) -> 161.8
B3: Median | C3: =MEDIAN(C6:C174) -> 37
B4: Stdev | C4: =STDEV(C6:C174) -> 307.72504
A5: Version | B5: Start_Date
A6: 1.1 | B6: 40105 | C6: =DATEDIF(B6,B7,"d") -> 0
A7: 1.2 | B7: 40105 | C7: =DATEDIF(B7,B8,"d") -> 37
A8: 2.0.0 | B8: 40142 | C8: =DATEDIF(B8,B9,"d") -> 9
A9: 2.0.1 | B9: 40151 | C9: =DATEDIF(B9,B10,"d") -> 52
A10: 2.0.2 | B10: 40203 | C10: =DATEDIF(B10,B11,"d") -> 711
A11: 3.0.0 | B11: 40914

Sheet Sheet2
